2019-03-03 12:17:31,661 ERROR: Exception on /index [GET] [in d:\program_files\python\lib\site-packages\flask\app.py:1761]
Traceback (most recent call last):
  File "d:\program_files\python\lib\site-packages\flask\app.py", line 2292, in wsgi_app
    response = self.full_dispatch_request()
  File "d:\program_files\python\lib\site-packages\flask\app.py", line 1815, in full_dispatch_request
    rv = self.handle_user_exception(e)
  File "d:\program_files\python\lib\site-packages\flask\app.py", line 1718, in handle_user_exception
    reraise(exc_type, exc_value, tb)
  File "d:\program_files\python\lib\site-packages\flask\_compat.py", line 35, in reraise
    raise value
  File "d:\program_files\python\lib\site-packages\flask\app.py", line 1813, in full_dispatch_request
    rv = self.dispatch_request()
  File "d:\program_files\python\lib\site-packages\flask\app.py", line 1799, in dispatch_request
    return self.view_functions[rule.endpoint](**req.view_args)
  File "D:\My Books\SIH2019\FutureIn2\app\routes.py", line 40, in index
    posts = current_user.followed_posts().paginate(
  File "d:\program_files\python\lib\site-packages\werkzeug\local.py", line 347, in __getattr__
    return getattr(self._get_current_object(), name)
AttributeError: 'AnonymousUserMixin' object has no attribute 'followed_posts'
2019-03-03 12:17:33,022 ERROR: Exception on /index [GET] [in d:\program_files\python\lib\site-packages\flask\app.py:1761]
Traceback (most recent call last):
  File "d:\program_files\python\lib\site-packages\flask\app.py", line 2292, in wsgi_app
    response = self.full_dispatch_request()
  File "d:\program_files\python\lib\site-packages\flask\app.py", line 1815, in full_dispatch_request
    rv = self.handle_user_exception(e)
  File "d:\program_files\python\lib\site-packages\flask\app.py", line 1718, in handle_user_exception
    reraise(exc_type, exc_value, tb)
  File "d:\program_files\python\lib\site-packages\flask\_compat.py", line 35, in reraise
    raise value
  File "d:\program_files\python\lib\site-packages\flask\app.py", line 1813, in full_dispatch_request
    rv = self.dispatch_request()
  File "d:\program_files\python\lib\site-packages\flask\app.py", line 1799, in dispatch_request
    return self.view_functions[rule.endpoint](**req.view_args)
  File "D:\My Books\SIH2019\FutureIn2\app\routes.py", line 40, in index
    posts = current_user.followed_posts().paginate(
  File "d:\program_files\python\lib\site-packages\werkzeug\local.py", line 347, in __getattr__
    return getattr(self._get_current_object(), name)
AttributeError: 'AnonymousUserMixin' object has no attribute 'followed_posts'
2019-03-03 12:19:57,749 INFO: Microblog startup [in D:\My Books\SIH2019\FutureIn2\app\__init__.py:52]
2019-03-03 12:21:01,391 INFO: Microblog startup [in D:\My Books\SIH2019\FutureIn2\app\__init__.py:52]
